<?xml version="1.0" encoding="utf-8"?>
<!-- This URDF was automatically created by SolidWorks to URDF Exporter! Originally created by Stephen Brawner (brawner@gmail.com) 
     Commit Version: 1.5.1-0-g916b5db  Build Version: 1.5.7152.31018
     For more information, please see http://wiki.ros.org/sw_urdf_exporter -->
<robot
  name="gantry_description">

  <link name="world">
  </link>
  
  <link name="base_link">
    <inertial>
      <origin rpy="0 0 0" xyz="0 0 0.95"/>
      <mass value="236"/>
      <inertia ixx="0" iyy="0" izz="0" ixy="0" ixz="0" iyz="0" />
    </inertial>
    <visual>
      <origin rpy="0 0 0" xyz="0 0 0.95"/>
      <geometry>
        <mesh filename="package://gantry_description/meshes/base_link.STL"/>
      </geometry>
      <material name="">
        <color rgba="0.89804 0.91765 0.92941 1"/>
      </material>
    </visual>
    <collision>
      <origin rpy="0 0 0" xyz="0 0 0.95"/>
      <geometry>
        <mesh filename="package://gantry_description/meshes/base_link.STL"/>
      </geometry>
    </collision>
  </link>

  <joint name="world_to_baselink" type="fixed">
    <origin rpy="0 0 0" xyz="0 0 0"/>
    <parent link="world"/>
    <child link="base_link"/>
    <axis xyz="0 0 0"/>
  </joint>
  
  
  <link name="left_bar">
    <inertial>
      <origin rpy="0 0 0" xyz="0 0 0.95"/>
      <mass value="24.263"/>
      <inertia ixx="0" iyy="0" izz="0" ixy="0" ixz="0" iyz="0" />
    </inertial>
    <visual>
      <origin rpy="0 0 0" xyz="0 0 0.95"/>
      <geometry>
        <mesh filename="package://gantry_description/meshes/left_bar.STL"/>
      </geometry>
      <material name="">
        <color rgba="0.89804 0.91765 0.92941 1"/>
      </material>
    </visual>
    <collision>
      <origin rpy="0 0 0" xyz="0 0 0.95"/>
      <geometry>
        <mesh filename="package://gantry_description/meshes/left_bar.STL"/>
      </geometry>
    </collision>
  </link>
  
  <joint name="f_left_bar" type="fixed">
    <origin rpy="0 0 0" xyz="0 0 0"/>
    <parent link="base_link"/>
    <child link="left_bar"/>
    <axis xyz="0 0 0"/>
  </joint>
  
  
  <link name="right_bar">
    <inertial>
      <origin rpy="0 0 0" xyz="0 0 0.95"/>
      <mass value="24.858"/>
      <inertia ixx="0" iyy="0" izz="0" ixy="0" ixz="0" iyz="0" />
    </inertial>
    <visual>
      <origin rpy="0 0 0" xyz="0 0 0.95"/>
      <geometry>
        <mesh filename="package://gantry_description/meshes/right_bar.STL"/>
      </geometry>
      <material name="">
        <color rgba="0.89804 0.91765 0.92941 1"/>
      </material>
    </visual>
    <collision>
      <origin rpy="0 0 0" xyz="0 0 0.95"/>
      <geometry>
        <mesh filename="package://gantry_description/meshes/right_bar.STL"/>
      </geometry>
    </collision>
  </link>


  <joint name="f_right_bar" type="fixed">
    <origin rpy="0 0 0" xyz="0 0 0"/>
    <parent link="base_link"/>
    <child link="right_bar"/>
    <axis xyz="0 0 0"/>
  </joint>
  
  <link name="right_motor">
    <inertial>
      <origin rpy="0 0 0" xyz="0 0 0.95"/>
      <mass value="0.512"/>
      <inertia ixx="0" iyy="0" izz="0" ixy="0" ixz="0" iyz="0" />
    </inertial>
    <visual>
      <origin rpy="0 0 0" xyz="0 0 0.95"/>
      <geometry>
        <mesh filename="package://gantry_description/meshes/right_motor.STL"/>
      </geometry>
      <material name="">
        <color rgba="1 1 1 1"/>
      </material>
    </visual>
    <collision>
      <origin rpy="0 0 0" xyz="0 0 0.95"/>
      <geometry>
        <mesh filename="package://gantry_description/meshes/right_motor.STL"/>
      </geometry>
    </collision>
  </link>
  
  
  <joint name="f_right_motor" type="fixed">
    <origin rpy="0 0 0" xyz="0 0 0"/>
    <parent link="right_bar"/>
    <child link="right_motor"/>
    <axis xyz="0 0 0"/>
  </joint>
  
  
  <link name="right_rod">
    <inertial>
      <origin rpy="0 0 0" xyz="0 0 0.95"/>
      <mass value="0.02709"/>
      <inertia ixx="4.5437E-05" iyy="4.0541E-06" izz="4.5437E-05" ixy="0" ixz="0" iyz="0" />
    </inertial>
    <visual>
      <origin rpy="0 0 0" xyz="0 0 0.95"/>
      <geometry>
        <mesh filename="package://gantry_description/meshes/right_rod.STL"/>
      </geometry>
      <material name="">
        <color rgba="1 0 0 1"/>
      </material>
    </visual>
    <collision>
      <origin rpy="0 0 0" xyz="0 0 0.95"/>
      <geometry>
        <mesh filename="package://gantry_description/meshes/right_rod.STL"/>
      </geometry>
    </collision>
  </link>
  
  
  <joint name="f_right_rod" type="fixed">
    <origin rpy="0 0 0" xyz="0 0 0"/>
    <parent link="right_motor"/>
    <child link="right_rod"/>
    <axis xyz="0 0 0"/>
  </joint>
  
  
  <link name="motion1_slider">
    <inertial>
      <origin rpy="0 0 0" xyz="0 0 0.95"/>
      <mass value="1.8544"/>
      <inertia ixx="0" iyy="0" izz="0" ixy="2.0988E-07" ixz="-4.5186E-05" iyz="1.6779E-07" />
    </inertial>
    <visual>
      <origin rpy="0 0 0" xyz="0 0 0.95"/>
      <geometry>
        <mesh filename="package://gantry_description/meshes/motion1_slider.STL"/>
      </geometry>
      <material name="">
        <color rgba="0.89804 0.91765 0.92941 1"/>
      </material>
    </visual>
    <collision>
      <origin rpy="0 0 0" xyz="0 0 0.95"/>
      <geometry>
        <mesh filename="package://gantry_description/meshes/motion1_slider.STL"/>
      </geometry>
    </collision>
  </link>
  
  
  <joint name="p_motion1" type="prismatic">
    <origin rpy="0 0 0" xyz="0 0 0"/>
    <parent link="right_rod"/>
    <child link="motion1_slider"/>
    <axis xyz="0 1 0"/>
    <limit effort="10" lower="-0.4" upper="0.4" velocity="50"/>
  </joint>
  
  
  <link name="top_bar">
    <inertial>
      <origin rpy="0 0 0" xyz="0 0 0.95"/>
      <mass value="10.652"/>
      <inertia ixx="0" iyy="0" izz="0" ixy="3.5377E-07" ixz="1.4909E-05" iyz="8.3927E-06" />
    </inertial>
    <visual>
      <origin rpy="0 0 0" xyz="0 0 0.95"/>
      <geometry>
        <mesh filename="package://gantry_description/meshes/top_bar.STL"/>
      </geometry>
      <material name="">
        <color rgba="0.89804 0.91765 0.92941 1"/>
      </material>
    </visual>
    <collision>
      <origin rpy="0 0 0" xyz="0 0 0.95"/>
      <geometry>
        <mesh filename="package://gantry_description/meshes/top_bar.STL"/>
      </geometry>
    </collision>
  </link>
  
  
  <joint name="f_top_bar" type="fixed">
    <origin rpy="0 0 0" xyz="0 0 0"/>
    <parent link="motion1_slider"/>
    <child link="top_bar"/>
    <axis xyz="0 0 0"/>
  </joint>


  <link name="top_motor">
    <inertial>
      <origin rpy="0 0 0" xyz="0 0 0.95"/>
      <mass value="0.512"/>
      <inertia ixx="0.00037705" iyy="0.00067285" izz="0.00067164" ixy="9.6148E-08" ixz="-2.118E-09" iyz="4.946E-08" />
    </inertial>
    <visual>
      <origin rpy="0 0 0" xyz="0 0 0.95"/>
      <geometry>
        <mesh filename="package://gantry_description/meshes/top_motor.STL"/>
      </geometry>
      <material name="">
        <color rgba="1 1 1 1"/>
      </material>
    </visual>
    <collision>
      <origin rpy="0 0 0" xyz="0 0 0.95"/>
      <geometry>
        <mesh filename="package://gantry_description/meshes/top_motor.STL"/>
      </geometry>
    </collision>
  </link>
  
  
  <joint name="f_top_motor" type="fixed">
    <origin rpy="0 0 0" xyz="0 0 0"/>
    <parent link="top_bar"/>
    <child link="top_motor"/>
    <axis xyz="0 0 0"/>
  </joint>
  
  
  <link name="top_rod">
    <inertial>
      <origin rpy="0 0 0" xyz="0 0 0.95"/>
      <mass value="0.02709"/>
      <inertia ixx="4.0541E-06" iyy="4.5437E-05" izz="4.5437E-05" ixy="1.4106E-11" ixz="-4.8609E-11" iyz="-3.8569E-11"/>
    </inertial>
    <visual>
      <origin rpy="0 0 0" xyz="0 0 0.95"/>
      <geometry>
        <mesh filename="package://gantry_description/meshes/top_rod.STL"/>
      </geometry>
      <material name="">
        <color rgba="0.68627 0.68627 0.68627 1"/>
      </material>
    </visual>
    <collision>
      <origin rpy="0 0 0" xyz="0 0 0.95"/>
      <geometry>
        <mesh filename="package://gantry_description/meshes/top_rod.STL"/>
      </geometry>
    </collision>
  </link>


  <joint name="f_top_rod" type="fixed">
    <origin rpy="0 0 0" xyz="0 0 0"/>
    <parent link="top_motor"/>
    <child link="top_rod"/>
    <axis xyz="0 0 0"/>
  </joint>


  <link name="motion2_slider">
    <inertial>
      <origin rpy="0 0 0" xyz="0 0 0.95"/>
      <mass value="6.9597"/>
      <inertia ixx="0" ixy="-2.0988E-07" iyy="0" izz="0" ixz="-1.7396E-07" iyz="-4.3519E-11" />
    </inertial>
    <visual>
      <origin rpy="0 0 0" xyz="0 0 0.95"/>
      <geometry>
        <mesh filename="package://gantry_description/meshes/motion2_slider.STL"/>
      </geometry>
      <material name="">
        <color rgba="0.89804 0.91765 0.92941 1"/>
      </material>
    </visual>
    <collision>
      <origin rpy="0 0 0" xyz="0 0 0.95"/>
      <geometry>
        <mesh filename="package://gantry_description/meshes/motion2_slider.STL"/>
      </geometry>
    </collision>
  </link>
  
  
  <joint name="p_motion2" type="prismatic">
    <origin rpy="0 0 0" xyz="0 0 0"/>
    <parent link="top_rod"/>
    <child link="motion2_slider"/>
    <axis xyz="1 0 0"/>
    <limit effort="10" lower="-0.4" upper="0.4" velocity="50"/>
  </joint>


  <transmission name="trans_p_motion1">
      <type>transmission_interface/SimpleTransmission</type>
      <joint name="p_motion1">
          <hardwareInterface>PositionJointInterface</hardwareInterface>
      </joint>
      <actuator name="p_motion1_motor">
          <hardwareInterface>PositionJointInterface</hardwareInterface>
          <mechanicalReduction>1</mechanicalReduction>
      </actuator>
  </transmission>
  
  <transmission name="trans_p_motion2">
      <type>transmission_interface/SimpleTransmission</type>
      <joint name="p_motion2">
          <hardwareInterface>PositionJointInterface</hardwareInterface>
      </joint>
      <actuator name="p_motion2_motor">
          <hardwareInterface>PositionJointInterface</hardwareInterface>
          <mechanicalReduction>1</mechanicalReduction>
      </actuator>
  </transmission>

  <gazebo>
    <plugin name="control" filename="libgazebo_ros_control.so"/>
  </gazebo>


  <gazebo>
    <plugin name="joint_state_publisher" filename="libgazebo_ros_joint_state_publisher.so">
      <jointName>p_motion1, p_motion2</jointName>
    </plugin>
  </gazebo>



</robot>