<?xml version="1.0" ?>
<!-- =================================================================================== -->
<!-- |    This document was autogenerated by xacro from pleatrobot.urdf.xacro          | -->
<!-- |    EDITING THIS FILE BY HAND IS NOT RECOMMENDED                                 | -->
<!-- =================================================================================== -->
<robot name="pleatrobot">

  <material name="Black">
    <color rgba="0.0 0.0 0.0 1.0"/>
  </material>
  <material name="Blue">
    <color rgba="0.0 0.0 0.8 1.0"/>
  </material>
  <material name="Green">
    <color rgba="0.0 0.8 0.0 1.0"/>
  </material>
  <material name="Grey">
    <color rgba="0.4 0.4 0.4 1.0"/>
  </material>
  <material name="Orange">
    <color rgba="1.0 0.423529411765 0.0392156862745 1.0"/>
  </material>
  <material name="Brown">
    <color rgba="0.870588235294 0.811764705882 0.764705882353 1.0"/>
  </material>
  <material name="Red">
    <color rgba="0.8 0.0 0.0 1.0"/>
  </material>
  <material name="White">
    <color rgba="1.0 1.0 1.0 1.0"/>
  </material>

  <link name="world">
  </link>
  
  <link name="base_link">
    <inertial>
      <origin rpy="0 0 0" xyz="0 0 0.95"/>
      <mass value="186.7"/>
      <inertia ixx="120" iyy="120" izz="120" ixy="0" ixz="0" iyz="0" />
    </inertial>
    <visual>
      <origin rpy="0 0 0" xyz="0 0 0.95"/>
      <geometry>
        <mesh filename="package://gantry_description/meshes/base_link.STL"/>
      </geometry>
      <material name="">
        <color rgba="0.89804 0.91765 0.92941 1"/>
      </material>
    </visual>
    <collision>
      <origin rpy="0 0 0" xyz="0 0 0.95"/>
      <geometry>
        <mesh filename="package://gantry_description/meshes/base_link.STL"/>
      </geometry>
    </collision>
  </link>

  <joint name="world_to_baselink" type="fixed">
    <origin rpy="0 0 0" xyz="0 0 0"/>
    <parent link="world"/>
    <child link="base_link"/>
    <axis xyz="0 0 0"/>
  </joint>
  
  
  <link name="left_bar">
    <inertial>
      <origin rpy="0 0 0" xyz="0.82653 0.0 1.85173"/>
      <mass value="24.263"/>
      <inertia ixx="6.57" iyy="0.03" izz="6.56" ixy="0" ixz="0" iyz="0" />
    </inertial>
    <visual>
      <origin rpy="0 0 0" xyz="0 0 0.95"/>
      <geometry>
        <mesh filename="package://gantry_description/meshes/left_bar.STL"/>
      </geometry>
      <material name="">
        <color rgba="0.89804 0.91765 0.92941 1"/>
      </material>
    </visual>
    <collision>
      <origin rpy="0 0 0" xyz="0 0 0.95"/>
      <geometry>
        <mesh filename="package://gantry_description/meshes/left_bar.STL"/>
      </geometry>
    </collision>
  </link>
  
  <joint name="f_left_bar" type="fixed">
    <origin rpy="0 0 0" xyz="0 0 0"/>
    <parent link="base_link"/>
    <child link="left_bar"/>
    <axis xyz="0 0 0"/>
  </joint>
  
  
  <link name="right_bar">
    <inertial>
      <origin rpy="0 0 0" xyz="-0.82689 0 1.85173"/>
      <mass value="24.263"/>
      <inertia ixx="6.57" iyy="0.03" izz="6.56" ixy="0" ixz="0" iyz="0" />
    </inertial>
    <visual>
      <origin rpy="0 0 0" xyz="0 0 0.95"/>
      <geometry>
        <mesh filename="package://gantry_description/meshes/right_bar.STL"/>
      </geometry>
      <material name="">
        <color rgba="0.89804 0.91765 0.92941 1"/>
      </material>
    </visual>
    <collision>
      <origin rpy="0 0 0" xyz="0 0 0.95"/>
      <geometry>
        <mesh filename="package://gantry_description/meshes/right_bar.STL"/>
      </geometry>
    </collision>
  </link>


  <joint name="f_right_bar" type="fixed">
    <origin rpy="0 0 0" xyz="0 0 0"/>
    <parent link="base_link"/>
    <child link="right_bar"/>
    <axis xyz="0 0 0"/>
  </joint>
  
  <link name="right_motor">
    <inertial>
      <origin rpy="0 0 0" xyz="-0.83094 -0.60801 1.93633"/>
      <mass value="0.512"/>
      <inertia ixx="0.00067287" iyy="0.00037705" izz="0.00067162" ixy="0" ixz="0" iyz="0" />
    </inertial>
    <visual>
      <origin rpy="0 0 0" xyz="0 0 0.95"/>
      <geometry>
        <mesh filename="package://gantry_description/meshes/right_motor.STL"/>
      </geometry>
      <material name="">
        <color rgba="1 1 1 1"/>
      </material>
    </visual>
    <collision>
      <origin rpy="0 0 0" xyz="0 0 0.95"/>
      <geometry>
        <mesh filename="package://gantry_description/meshes/right_motor.STL"/>
      </geometry>
    </collision>
  </link>
  
  
  <joint name="f_right_motor" type="fixed">
    <origin rpy="0 0 0" xyz="0 0 0"/>
    <parent link="right_bar"/>
    <child link="right_motor"/>
    <axis xyz="0 0 0"/>
  </joint>
  
  
  <link name="right_rod">
    <inertial>
      <origin rpy="0 0 0" xyz="-0.82757 0.09458 1.93633"/>
      <mass value="0.02709"/>
      <inertia ixx="4.5437E-05" iyy="4.0541E-06" izz="4.5437E-05" ixy="0" ixz="0" iyz="0" />
    </inertial>
    <visual>
      <origin rpy="0 0 0" xyz="0 0 0.95"/>
      <geometry>
        <mesh filename="package://gantry_description/meshes/right_rod.STL"/>
      </geometry>
      <material name="">
        <color rgba="0.89804 0.91765 0.92941 1"/>
      </material>
    </visual>
    <collision>
      <origin rpy="0 0 0" xyz="0 0 0.95"/>
      <geometry>
        <mesh filename="package://gantry_description/meshes/right_rod.STL"/>
      </geometry>
    </collision>
  </link>
  
  
  <joint name="f_right_rod" type="fixed">
    <origin rpy="0 0 0" xyz="0 0 0"/>
    <parent link="right_motor"/>
    <child link="right_rod"/>
    <axis xyz="0 0 0"/>
  </joint>
  
  
  <link name="motion1_slider">
    <inertial>
      <origin rpy="0 0 0" xyz="-0.82949 0.07672 1.94128"/>
      <mass value="1.8544"/>
      <inertia ixx="0.0032532" iyy="2.0988E-07" izz="0.003516" ixy="2.0988E-07" ixz="-4.5186E-05" iyz="1.6779E-07" />
    </inertial>
    <visual>
      <origin rpy="0 0 0" xyz="0 0 0.95"/>
      <geometry>
        <mesh filename="package://gantry_description/meshes/motion1_slider.STL"/>
      </geometry>
      <material name="">
        <color rgba="0.89804 0.91765 0.92941 1"/>
      </material>
    </visual>
    <collision>
      <origin rpy="0 0 0" xyz="0 0 0.95"/>
      <geometry>
        <mesh filename="package://gantry_description/meshes/motion1_slider.STL"/>
      </geometry>
    </collision>
  </link>
  
  
  <joint name="p_motion1" type="prismatic">
    <origin rpy="0 0 0" xyz="0 0 0"/>
    <parent link="right_rod"/>
    <child link="motion1_slider"/>
    <axis xyz="0 1 0"/>
    <limit effort="10" lower="-0.4" upper="0.4" velocity="50"/>
  </joint>
  
  
  <link name="top_bar">
    <inertial>
      <origin rpy="0 0 0" xyz="0.00405 0.07701 2.0363"/>
      <mass value="10.752"/>
      <inertia ixx="0.01" iyy="1.89" izz="1.89" ixy="3.5377E-07" ixz="1.4909E-05" iyz="8.3927E-06" />
    </inertial>
    <visual>
      <origin rpy="0 0 0" xyz="0 0 0.95"/>
      <geometry>
        <mesh filename="package://gantry_description/meshes/top_bar.STL"/>
      </geometry>
      <material name="">
        <color rgba="0.89804 0.91765 0.92941 1"/>
      </material>
    </visual>
    <collision>
      <origin rpy="0 0 0" xyz="0 0 0.95"/>
      <geometry>
        <mesh filename="package://gantry_description/meshes/top_bar.STL"/>
      </geometry>
    </collision>
  </link>
  
  
  <joint name="f_top_bar" type="fixed">
    <origin rpy="0 0 0" xyz="0 0 0"/>
    <parent link="motion1_slider"/>
    <child link="top_bar"/>
    <axis xyz="0 0 0"/>
  </joint>


  <link name="top_motor">
    <inertial>
      <origin rpy="0 0 0" xyz="-0.60801 0.07702 2.1295"/>
      <mass value="0.512"/>
      <inertia ixx="0.00037705" iyy="0.00067285" izz="0.00067164" ixy="9.6148E-08" ixz="-2.118E-09" iyz="4.946E-08" />
    </inertial>
    <visual>
      <origin rpy="0 0 0" xyz="0 0 0.95"/>
      <geometry>
        <mesh filename="package://gantry_description/meshes/top_motor.STL"/>
      </geometry>
      <material name="">
        <color rgba="1 1 1 1"/>
      </material>
    </visual>
    <collision>
      <origin rpy="0 0 0" xyz="0 0 0.95"/>
      <geometry>
        <mesh filename="package://gantry_description/meshes/top_motor.STL"/>
      </geometry>
    </collision>
  </link>
  
  
  <joint name="f_top_motor" type="fixed">
    <origin rpy="0 0 0" xyz="0 0 0"/>
    <parent link="top_bar"/>
    <child link="top_motor"/>
    <axis xyz="0 0 0"/>
  </joint>
  
  
  <link name="top_rod">
    <inertial>
      <origin rpy="0 0 0" xyz="0.09323 0.07783 2.1295"/>
      <mass value="0.02709"/>
      <inertia ixx="4.0541E-06" iyy="4.5437E-05" izz="4.5437E-05" ixy="1.4106E-11" ixz="-4.8609E-11" iyz="-3.8569E-11"/>
    </inertial>
    <visual>
      <origin rpy="0 0 0" xyz="0 0 0.95"/>
      <geometry>
        <mesh filename="package://gantry_description/meshes/top_rod.STL"/>
      </geometry>
      <material name="">
        <color rgba="0.68627 0.68627 0.68627 1"/>
      </material>
    </visual>
    <collision>
      <origin rpy="0 0 0" xyz="0 0 0.95"/>
      <geometry>
        <mesh filename="package://gantry_description/meshes/top_rod.STL"/>
      </geometry>
    </collision>
  </link>


  <joint name="f_top_rod" type="fixed">
    <origin rpy="0 0 0" xyz="0 0 0"/>
    <parent link="top_motor"/>
    <child link="top_rod"/>
    <axis xyz="0 0 0"/>
  </joint>


  <link name="motion2_slider">
    <inertial>
      <origin rpy="0 0 0" xyz="0.04102 0.07292 2.0347"/>
      <mass value="6.9597"/>
      <inertia ixx="0.020511" ixy="-2.0988E-07" iyy="0.037035" izz="0.054451" ixz="-1.7396E-07" iyz="-4.3519E-11" />
    </inertial>
    <visual>
      <origin rpy="0 0 0" xyz="0 0 0.95"/>
      <geometry>
        <mesh filename="package://gantry_description/meshes/motion2_slider.STL"/>
      </geometry>
      <material name="">
        <color rgba="0.89804 0.91765 0.92941 1"/>
      </material>
    </visual>
    <collision>
      <origin rpy="0 0 0" xyz="0 0 0.95"/>
      <geometry>
        <mesh filename="package://gantry_description/meshes/motion2_slider.STL"/>
      </geometry>
    </collision>
  </link>
  
  
  <joint name="p_motion2" type="prismatic">
    <origin rpy="0 0 0" xyz="0 0 0"/>
    <parent link="top_rod"/>
    <child link="motion2_slider"/>
    <axis xyz="1 0 0"/>
    <limit effort="10" lower="-0.4" upper="0.4" velocity="50"/>
  </joint>
  
  
  <!--joint between {parent} and link_0-->
  <joint name="motion2_slider_pleatrobot_joint" type="fixed">
    <origin rpy="0 3.1416 0" xyz="-0.035 0.075 1.98253"/>
    <parent link="motion2_slider"/>
    <child link="pleatrobot_link_0"/>
  </joint>
  
  
  <link name="pleatrobot_link_0">
    <inertial>
      <origin rpy="0 0 0" xyz="-0.1 0 0.07"/>
      <mass value="5"/>
      <inertia ixx="0.05" ixy="0" ixz="0" iyy="0.06" iyz="0" izz="0.03"/>
    </inertial>
    <visual>
      <origin rpy="0 0 0" xyz="0 0 0"/>
      <geometry>
        <mesh filename="package://pleatrobot_description/meshes/iiwa7/visual/link_0.stl"/>
      </geometry>
      <material name="Grey"/>
    </visual>
    <collision>
      <origin rpy="0 0 0" xyz="0 0 0"/>
      <geometry>
        <mesh filename="package://pleatrobot_description/meshes/iiwa7/collision/link_0.stl"/>
      </geometry>
      <material name="Grey"/>
    </collision>
    <self_collision_checking>
      <origin rpy="0 0 0" xyz="0 0 0"/>
      <geometry>
        <capsule length="0.25" radius="0.15"/>
      </geometry>
    </self_collision_checking>
  </link>
  
  
  <!-- joint between link_0 and link_1 -->
  <joint name="pleatrobot_joint_1" type="revolute">
    <parent link="pleatrobot_link_0"/>
    <child link="pleatrobot_link_1"/>
    <origin rpy="0 0 0" xyz="0 0 0.15"/>
    <axis xyz="0 0 1"/>
    <limit effort="300" lower="-2.96705972839" upper="2.96705972839" velocity="10"/>
    <safety_controller k_position="100" k_velocity="2" soft_lower_limit="-2.93215314335" soft_upper_limit="2.93215314335"/>
    <dynamics damping="0.5"/>
  </joint>
  
  
  <link name="pleatrobot_link_1">
    <inertial>
      <origin rpy="0 0 0" xyz="0 -0.03 0.12"/>
      <mass value="3.4525"/>
      <inertia ixx="0.02183" ixy="0" ixz="0" iyy="0.007703" iyz="-0.003887" izz="0.02083"/>
    </inertial>
    <visual>
      <origin rpy="0 0 0" xyz="0 0 0.0075"/>
      <geometry>
        <mesh filename="package://pleatrobot_description/meshes/iiwa7/visual/link_1.stl"/>
      </geometry>
      <material name="Orange"/>
    </visual>
    <collision>
      <origin rpy="0 0 0" xyz="0 0 0.0075"/>
      <geometry>
        <mesh filename="package://pleatrobot_description/meshes/iiwa7/collision/link_1.stl"/>
      </geometry>
      <material name="Orange"/>
    </collision>
  </link>
  
  
  <joint name="pleatrobot_joint_2" type="revolute">
    <parent link="pleatrobot_link_1"/>
    <child link="pleatrobot_link_2"/>
    <origin rpy="1.57079632679   0 3.14159265359" xyz="0 0 0.19"/>
    <axis xyz="0 0 1"/>
    <limit effort="300" lower="-2.09439510239" upper="2.09439510239" velocity="10"/>
    <safety_controller k_position="100" k_velocity="2" soft_lower_limit="-2.05948851735" soft_upper_limit="2.05948851735"/>
    <dynamics damping="0.5"/>
  </joint>
  
  
  <link name="pleatrobot_link_2">
    <inertial>
      <origin rpy="0 0 0" xyz="0.0003 0.059 0.042"/>
      <mass value="3.4821"/>
      <inertia ixx="0.02076" ixy="0" ixz="-0.003626" iyy="0.02179" iyz="0" izz="0.00779"/>
    </inertial>
    <visual>
      <origin rpy="0 0 0" xyz="0 0 0"/>
      <geometry>
        <mesh filename="package://pleatrobot_description/meshes/iiwa7/visual/link_2.stl"/>
      </geometry>
      <material name="Orange"/>
    </visual>
    <collision>
      <origin rpy="0 0 0" xyz="0 0 0"/>
      <geometry>
        <mesh filename="package://pleatrobot_description/meshes/iiwa7/collision/link_2.stl"/>
      </geometry>
      <material name="Orange"/>
    </collision>
  </link>
  
  
  <joint name="pleatrobot_joint_3" type="revolute">
    <parent link="pleatrobot_link_2"/>
    <child link="pleatrobot_link_3"/>
    <origin rpy="1.57079632679 0 3.14159265359" xyz="0 0.21 0"/>
    <axis xyz="0 0 1"/>
    <limit effort="300" lower="-2.96705972839" upper="2.96705972839" velocity="10"/>
    <safety_controller k_position="100" k_velocity="2" soft_lower_limit="-2.93215314335" soft_upper_limit="2.93215314335"/>
    <dynamics damping="0.5"/>
  </joint>
  
  
  <link name="pleatrobot_link_3">
    <inertial>
      <origin rpy="0 0 0" xyz="0 0.03 0.13"/>
      <mass value="4.05623"/>
      <inertia ixx="0.03204" ixy="0" ixz="0" iyy="0.00972" iyz="0.006227" izz="0.03042"/>
    </inertial>
    <visual>
      <origin rpy="0 0 0" xyz="0 0 -0.026"/>
      <geometry>
        <mesh filename="package://pleatrobot_description/meshes/iiwa7/visual/link_3.stl"/>
      </geometry>
      <material name="Orange"/>
    </visual>
    <collision>
      <origin rpy="0 0 0" xyz="0 0 -0.026"/>
      <geometry>
        <mesh filename="package://pleatrobot_description/meshes/iiwa7/collision/link_3.stl"/>
      </geometry>
      <material name="Orange"/>
    </collision>
  </link>
  
  
  <joint name="pleatrobot_joint_4" type="revolute">
    <parent link="pleatrobot_link_3"/>
    <child link="pleatrobot_link_4"/>
    <origin rpy="1.57079632679 0 0" xyz="0 0 0.19"/>
    <axis xyz="0 0 1"/>
    <limit effort="300" lower="-2.09439510239" upper="2.09439510239" velocity="10"/>
    <safety_controller k_position="100" k_velocity="2" soft_lower_limit="-2.05948851735" soft_upper_limit="2.05948851735"/>
    <dynamics damping="0.5"/>
  </joint>
  
  
  <link name="pleatrobot_link_4">
    <inertial>
      <origin rpy="0 0 0" xyz="0 0.067 0.034"/>
      <mass value="3.4822"/>
      <inertia ixx="0.02178" ixy="0" ixz="0" iyy="0.02075" iyz="-0.003625" izz="0.007785"/>
    </inertial>
    <visual>
      <origin rpy="0 0 0" xyz="0 0 0"/>
      <geometry>
        <mesh filename="package://pleatrobot_description/meshes/iiwa7/visual/link_4.stl"/>
      </geometry>
      <material name="Orange"/>
    </visual>
    <collision>
      <origin rpy="0 0 0" xyz="0 0 0"/>
      <geometry>
        <mesh filename="package://pleatrobot_description/meshes/iiwa7/collision/link_4.stl"/>
      </geometry>
      <material name="Orange"/>
    </collision>
  </link>
  
  
  <joint name="pleatrobot_joint_5" type="revolute">
    <parent link="pleatrobot_link_4"/>
    <child link="pleatrobot_link_5"/>
    <origin rpy="-1.57079632679 3.14159265359 0" xyz="0 0.21 0"/>
    <axis xyz="0 0 1"/>
    <limit effort="300" lower="-2.96705972839" upper="2.96705972839" velocity="10"/>
    <safety_controller k_position="100" k_velocity="2" soft_lower_limit="-2.93215314335" soft_upper_limit="2.93215314335"/>
    <dynamics damping="0.5"/>
  </joint>
  
  
  <link name="pleatrobot_link_5">
    <inertial>
      <origin rpy="0 0 0" xyz="0.0001 0.021 0.076"/>
      <mass value="2.1633"/>
      <inertia ixx="0.01287" ixy="0" ixz="0" iyy="0.005708" iyz="-0.003946" izz="0.01112"/>
    </inertial>
    <visual>
      <origin rpy="0 0 0" xyz="0 0 -0.026"/>
      <geometry>
        <mesh filename="package://pleatrobot_description/meshes/iiwa7/visual/link_5.stl"/>
      </geometry>
      <material name="Orange"/>
    </visual>
    <collision>
      <origin rpy="0 0 0" xyz="0 0 -0.026"/>
      <geometry>
        <mesh filename="package://pleatrobot_description/meshes/iiwa7/collision/link_5.stl"/>
      </geometry>
      <material name="Orange"/>
    </collision>
  </link>
  
  
  <joint name="pleatrobot_joint_6" type="revolute">
    <parent link="pleatrobot_link_5"/>
    <child link="pleatrobot_link_6"/>
    <origin rpy="1.57079632679 0 0" xyz="0 0.06070 0.19"/>
    <axis xyz="0 0 1"/>
    <limit effort="300" lower="-2.09439510239" upper="2.09439510239" velocity="10"/>
    <safety_controller k_position="100" k_velocity="2" soft_lower_limit="-2.05948851735" soft_upper_limit="2.05948851735"/>
    <dynamics damping="0.5"/>
  </joint>
  
  
  <link name="pleatrobot_link_6">
    <inertial>
      <origin rpy="0 0 0" xyz="0 0.0006 0.0004"/>
      <mass value="2.3466"/>
      <inertia ixx="0.006509" ixy="0" ixz="0" iyy="0.006259" iyz="0.00031891" izz="0.004527"/>
    </inertial>
    <visual>
      <origin rpy="0 0 0" xyz="0 0 0"/>
      <geometry>
        <mesh filename="package://pleatrobot_description/meshes/iiwa7/visual/link_6.stl"/>
      </geometry>
      <material name="Orange"/>
    </visual>
    <collision>
      <origin rpy="0 0 0" xyz="0 0 0"/>
      <geometry>
        <mesh filename="package://pleatrobot_description/meshes/iiwa7/collision/link_6.stl"/>
      </geometry>
      <material name="Orange"/>
    </collision>
  </link>
  
  
  <joint name="pleatrobot_joint_7" type="revolute">
    <parent link="pleatrobot_link_6"/>
    <child link="pleatrobot_link_7"/>
    <origin rpy="-1.57079632679 3.14159265359 0" xyz="0 0.081 0.06070"/>
    <axis xyz="0 0 1"/>
    <limit effort="300" lower="-3.05432619099" upper="3.05432619099" velocity="10"/>
    <safety_controller k_position="100" k_velocity="2" soft_lower_limit="-3.01941960595" soft_upper_limit="3.01941960595"/>
    <dynamics damping="0.5"/>
  </joint>
  
  
  <link name="pleatrobot_link_7">
    <inertial>
      <origin rpy="0 0 0" xyz="0 0 0.02"/>
      <mass value="3.129"/>
      <inertia ixx="0.01464" ixy="0.0005912" ixz="0" iyy="0.01465" iyz="0" izz="0.002872"/>
    </inertial>
    <visual>
      <origin rpy="0 0 0" xyz="0 0 -0.0005"/>
      <geometry>
        <mesh filename="package://pleatrobot_description/meshes/iiwa7/visual/link_7.stl"/>
      </geometry>
      <material name="Grey"/>
    </visual>
    <collision>
      <origin rpy="0 0 0" xyz="0 0 -0.0005"/>
      <geometry>
        <mesh filename="package://pleatrobot_description/meshes/iiwa7/collision/link_7.stl"/>
      </geometry>
      <material name="Grey"/>
    </collision>
  </link>
  
  
  <joint name="pleatrobot_joint_ee" type="fixed">
    <parent link="pleatrobot_link_7"/>
    <child link="gripper_base_link"/>
    <origin rpy="-1.5708 0 0" xyz="0 0 0"/>
  </joint>
  
    
  <link name="gripper_base_link">
    <inertial>
      <origin xyz="-1.2189E-07 1.2713 2.1759E-06" rpy="0 0 0" />
      <mass value="0.20104" />
      <inertia ixx="0.00012096" iyy="0.00021064" izz="0.00012095" ixy="-3.4543E-10" ixz="7.792E-11" iyz="2.2037E-09"/>
    </inertial>
    <visual>
      <origin
        xyz="0 1.21 0"
        rpy="0 0 0" />
      <geometry>
        <mesh
          filename="package://gripper_description/meshes/base_link.STL" />
      </geometry>
      <material
        name="">
        <color
          rgba="0.79216 0.81961 0.93333 1" />
      </material>
    </visual>
    <collision>
      <origin
        xyz="0 1.21 0"
        rpy="0 0 0" />
      <geometry>
        <mesh
          filename="package://gripper_description/meshes/base_link.STL" />
      </geometry>
    </collision>
  </link>


  <link name="01_child">
    <inertial>
      <origin xyz="0.0094532 -0.6 -0.0033489" rpy="0 0 0" />
      <mass value="1.3212" />
      <inertia ixx="0.00226" iyy="0.0128225" izz="0.01281505" ixy="0" ixz="0.0016" iyz="0" />
    </inertial>
    <visual>
      <origin
        xyz="0 1.21 0"
        rpy="0 0 0" />
      <geometry>
        <mesh
          filename="package://gripper_description/meshes/01_child.STL" />
      </geometry>
      <material
        name="">
        <color
          rgba="0.79216 0.81961 0.93333 1" />
      </material>
    </visual>
    <collision>
      <origin
        xyz="0 1.21 0"
        rpy="0 0 0" />
      <geometry>
        <mesh
          filename="package://gripper_description/meshes/01_child.STL" />
      </geometry>
    </collision>
  </link>


  <joint name="f_01child" type="fixed">
    <origin
      xyz="0 0 0"
      rpy="0 0 0" />
    <parent
      link="gripper_base_link" />
    <child
      link="01_child" />
    <axis
      xyz="0 0 0" />
  </joint>


  <link name="jaw1">
    <inertial>
      <origin xyz="-0.0085346 0.047394 0.082598" rpy="0 0 0" />
      <mass value="0.40493" />
      <inertia ixx="0.00035017" iyy="0.00038396" izz="0.00025634" ixy="0" ixz="0" iyz="0" />
    </inertial>
    <visual>
      <origin
        xyz="0 0 0"
        rpy="0 0 0" />
      <geometry>
        <mesh
          filename="package://gripper_description/meshes/jaw1.STL" />
      </geometry>
      <material
        name="">
        <color
          rgba="0.82745 0.69804 0.4902 1" />
      </material>
    </visual>
    <collision>
      <origin
        xyz="0 0 0"
        rpy="0 0 0" />
      <geometry>
        <mesh
          filename="package://gripper_description/meshes/jaw1.STL" />
      </geometry>
    </collision>
  </link>
 
 
  <joint name="fixed_jaw1" type="fixed">
    <origin
      xyz="0.025 -0.303 0"
      rpy="1.5708 -1.5708 3.14159" />
    <parent
      link="01_child" />
    <child
      link="jaw1" />
    <axis
      xyz="0 0 0" />
    <limit
      lower="-0.0872665"
      upper="0.0872665"
      effort="50"
      velocity="100" />
  </joint>


  <link name="rod1">
    <inertial>
      <origin xyz="-0.00016212 0.079673 -0.00023128" rpy="0 0 0" />
      <mass value="0.23263" />
      <inertia ixx="0.00021456" iyy="5.3561E-05" izz="0.00022185" ixy="0" ixz="0" iyz="0" />
    </inertial>
    <visual>
      <origin
        xyz="0 0 0"
        rpy="0 0 0" />
      <geometry>
        <mesh
          filename="package://gripper_description/meshes/rod1.STL" />
      </geometry>
      <material
        name="">
        <color
          rgba="0.52941 0.54902 0.54902 1" />
      </material>
    </visual>
    <collision>
      <origin
        xyz="0 0 0"
        rpy="0 0 0" />
      <geometry>
        <mesh
          filename="package://gripper_description/meshes/rod1.STL" />
      </geometry>
    </collision>
  </link>
  
  
  <joint name="c_rod1" type="continuous">
    <origin
      xyz="-0.081888 0 0"
      rpy="3.1416 0.58586 1.5708" />
    <parent
      link="jaw1" />
    <child
      link="rod1" />
    <axis
      xyz="0 1 0" />
    <limit
      effort="50"
      velocity="100" />
  </joint>
  
  
  <link name="rod2">
    <inertial>
      <origin xyz="-0.098 -1.328 8.1314E-17" rpy="0 0 0" />
      <mass value="0.033326" />
      <inertia ixx="6.3581E-07" iyy="6.3516E-05" izz="6.3516E-05" ixy="3.8774E-23" ixz="1.6156E-23" iyz="-2.6552E-25" />
    </inertial>
    <visual>
      <origin
        xyz="0 1.21 0"
        rpy="0 0 0" />
      <geometry>
        <mesh
          filename="package://gripper_description/meshes/rod2.STL" />
      </geometry>
      <material
        name="">
        <color
          rgba="0.79216 0.81961 0.93333 1" />
      </material>
    </visual>
    <collision>
      <origin
        xyz="0 1.21 0"
        rpy="0 0 0" />
      <geometry>
        <mesh
          filename="package://gripper_description/meshes/rod2.STL" />
      </geometry>
    </collision>
  </link>
  
  
  <joint name="f_rod2" type="fixed">
    <origin
      xyz="0 0 0"
      rpy="0 0 0" />
    <parent
      link="01_child" />
    <child
      link="rod2" />
    <axis
      xyz="0 0 0" />
  </joint>
  
  
  <link name="jaw2">
    <inertial>
      <origin xyz="-0.063785 -0.2 -0.002598" rpy="0 0 0" />
      <mass value="0.81068" />
      <inertia ixx="0.0007992" iyy="0.00051604" izz="0.00010843" ixy="0.00060318" ixz="-1.2528E-07" iyz="-2.7791E-07" />
    </inertial>
    <visual>
      <origin
        xyz="0 1.21 0"
        rpy="0 0 0" />
      <geometry>
        <mesh
          filename="package://gripper_description/meshes/jaw2.STL" />
      </geometry>
      <material
        name="">
        <color
          rgba="0.82745 0.69804 0.4902 1" />
      </material>
    </visual>
    <collision>
      <origin
        xyz="0 1.21 0"
        rpy="0 0 0" />
      <geometry>
        <mesh
          filename="package://gripper_description/meshes/jaw2.STL" />
      </geometry>
    </collision>
  </link>
  
  
  <joint name="p_jaw2" type="prismatic">
    <origin
      xyz="0 0 0"
      rpy="0 0 0" />
    <parent
      link="rod2" />
    <child
      link="jaw2" />
    <axis
      xyz="-1 0 0" />
    <limit
      lower="0"
      upper="0.05"
      effort="50"
      velocity="100" />
  </joint>
  
  
  <link name="rod3">
    <inertial>
      <origin xyz="-0.000287482481318269 0.0796731129142511 2.27008169670917E-05" rpy="0 0 0" />
      <mass value="0.232866245737791" />
      <inertia ixx="0.000223656460602869" iyy="5.35773404241321E-05" izz="0.000212754182688039" ixy="-4.85120700596206E-13" ixz="7.44206671716712E-07" iyz="1.44557114747249E-11" />
    </inertial>
    <visual>
      <origin
        xyz="0 0 0"
        rpy="0 0 0" />
      <geometry>
        <mesh
          filename="package://gripper_description/meshes/rod3.STL" />
      </geometry>
      <material
        name="">
        <color
          rgba="0.529411764705882 0.549019607843137 0.549019607843137 1" />
      </material>
    </visual>
    <collision>
      <origin
        xyz="0 0 0"
        rpy="0 0 0" />
      <geometry>
        <mesh
          filename="package://gripper_description/meshes/rod3.STL" />
      </geometry>
    </collision>
  </link>
  
  
  <joint name="c_rod3" type="continuous">
    <origin
      xyz="-0.025 -0.303 0.081888"
      rpy="-1.5708 0 -0.55284" />
    <parent
      link="jaw2" />
    <child
      link="rod3" />
    <axis
      xyz="0 1 0" />
    <limit
      effort="50"
      velocity="100" />
  </joint>

  <link name="tool_tip"/>

  <joint name="tool_tip_pose" type="fixed">
    <parent link="pleatrobot_link_7"/>
    <child link="tool_tip"/>
    <origin xyz="0 0 0.3" rpy="0 0 0"/>
  </joint>


  

  <!-- Link0 -->
  <gazebo reference="pleatrobot_link_0">
    <material>Gazebo/Grey</material>
    <mu1>0.2</mu1>
    <mu2>0.2</mu2>
  </gazebo>
  <!-- Link1 -->
  <gazebo reference="pleatrobot_link_1">
    <material>Gazebo/Orange</material>
    <mu1>0.2</mu1>
    <mu2>0.2</mu2>
  </gazebo>
  <!-- Link2 -->
  <gazebo reference="pleatrobot_link_2">
    <material>Gazebo/Orange</material>
    <mu1>0.2</mu1>
    <mu2>0.2</mu2>
  </gazebo>
  <!-- Link3 -->
  <gazebo reference="pleatrobot_link_3">
    <material>Gazebo/Orange</material>
    <mu1>0.2</mu1>
    <mu2>0.2</mu2>
  </gazebo>
  <!-- Link4 -->
  <gazebo reference="pleatrobot_link_4">
    <material>Gazebo/Orange</material>
    <mu1>0.2</mu1>
    <mu2>0.2</mu2>
  </gazebo>
  <!-- Link5 -->
  <gazebo reference="pleatrobot_link_5">
    <material>Gazebo/Orange</material>
    <mu1>0.2</mu1>
    <mu2>0.2</mu2>
  </gazebo>
  <!-- Link6 -->
  <gazebo reference="pleatrobot_link_6">
    <material>Gazebo/Orange</material>
    <mu1>0.2</mu1>
    <mu2>0.2</mu2>
  </gazebo>
  <!-- Link7 -->
  <gazebo reference="pleatrobot_link_7">
    <material>Gazebo/Grey</material>
    <mu1>0.2</mu1>
    <mu2>0.2</mu2>
  </gazebo>

  
  <!-- <xacro:pleatrobot_transmission hardware_interface="${hardware_interface}"/> -->
  <transmission name="trans_p_motion1">
      <type>transmission_interface/SimpleTransmission</type>
      <joint name="p_motion1">
          <hardwareInterface>PositionJointInterface</hardwareInterface>
      </joint>
      <actuator name="p_motion1_motor">
          <hardwareInterface>PositionJointInterface</hardwareInterface>
          <mechanicalReduction>1</mechanicalReduction>
      </actuator>
  </transmission>
  
  <transmission name="trans_p_motion2">
      <type>transmission_interface/SimpleTransmission</type>
      <joint name="p_motion2">
          <hardwareInterface>PositionJointInterface</hardwareInterface>
      </joint>
      <actuator name="p_motion2_motor">
          <hardwareInterface>PositionJointInterface</hardwareInterface>
          <mechanicalReduction>1</mechanicalReduction>
      </actuator>
  </transmission>
  
  <transmission name="trans_pleatrobot_joint_1">
      <type>transmission_interface/SimpleTransmission</type>
      <joint name="pleatrobot_joint_1">
          <hardwareInterface>PositionJointInterface</hardwareInterface>
      </joint>
      <actuator name="pleatrobot_joint_1_motor">
          <hardwareInterface>PositionJointInterface</hardwareInterface>
          <mechanicalReduction>1</mechanicalReduction>
      </actuator>
  </transmission>
  
  <transmission name="trans_pleatrobot_joint_2">
      <type>transmission_interface/SimpleTransmission</type>
      <joint name="pleatrobot_joint_2">
          <hardwareInterface>PositionJointInterface</hardwareInterface>
      </joint>
      <actuator name="pleatrobot_joint_2_motor">
          <hardwareInterface>PositionJointInterface</hardwareInterface>
          <mechanicalReduction>1</mechanicalReduction>
      </actuator>
  </transmission>
  
  <transmission name="trans_pleatrobot_joint_3">
      <type>transmission_interface/SimpleTransmission</type>
      <joint name="pleatrobot_joint_3">
          <hardwareInterface>PositionJointInterface</hardwareInterface>
      </joint>
      <actuator name="pleatrobot_joint_3_motor">
          <hardwareInterface>PositionJointInterface</hardwareInterface>
          <mechanicalReduction>1</mechanicalReduction>
      </actuator>
  </transmission>
  
  <transmission name="trans_pleatrobot_joint_4">
      <type>transmission_interface/SimpleTransmission</type>
      <joint name="pleatrobot_joint_4">
          <hardwareInterface>PositionJointInterface</hardwareInterface>
      </joint>
      <actuator name="pleatrobot_joint_4_motor">
          <hardwareInterface>PositionJointInterface</hardwareInterface>
          <mechanicalReduction>1</mechanicalReduction>
      </actuator>
  </transmission>
  
  <transmission name="trans_pleatrobot_joint_5">
      <type>transmission_interface/SimpleTransmission</type>
      <joint name="pleatrobot_joint_5">
          <hardwareInterface>PositionJointInterface</hardwareInterface>
      </joint>
      <actuator name="pleatrobot_joint_5_motor">
          <hardwareInterface>PositionJointInterface</hardwareInterface>
          <mechanicalReduction>1</mechanicalReduction>
      </actuator>
  </transmission>
  
  <transmission name="trans_pleatrobot_joint_6">
      <type>transmission_interface/SimpleTransmission</type>
      <joint name="pleatrobot_joint_6">
          <hardwareInterface>PositionJointInterface</hardwareInterface>
      </joint>
      <actuator name="pleatrobot_joint_6_motor">
          <hardwareInterface>PositionJointInterface</hardwareInterface>
          <mechanicalReduction>1</mechanicalReduction>
      </actuator>
  </transmission>
  
  <transmission name="trans_pleatrobot_joint_7">
      <type>transmission_interface/SimpleTransmission</type>
      <joint name="pleatrobot_joint_7">
          <hardwareInterface>PositionJointInterface</hardwareInterface>
      </joint>
      <actuator name="pleatrobot_joint_7_motor">
          <hardwareInterface>PositionJointInterface</hardwareInterface>
          <mechanicalReduction>1</mechanicalReduction>
      </actuator>
  </transmission>
  
  <transmission name="trans_c_rod1">
      <type>transmission_interface/SimpleTransmission</type>
      <joint name="c_rod1">
          <hardwareInterface>PositionJointInterface</hardwareInterface>
      </joint>
      <actuator name="c_rod1_motor">
          <hardwareInterface>PositionJointInterface</hardwareInterface>
          <mechanicalReduction>1</mechanicalReduction>
      </actuator>
  </transmission>
  
  <transmission name="trans_p_jaw2">
      <type>transmission_interface/SimpleTransmission</type>
      <joint name="p_jaw2">
          <hardwareInterface>PositionJointInterface</hardwareInterface>
      </joint>
      <actuator name="p_jaw2_motor">
          <hardwareInterface>PositionJointInterface</hardwareInterface>
          <mechanicalReduction>1</mechanicalReduction>
      </actuator>
  </transmission>
  
  <transmission name="trans_c_rod3">
      <type>transmission_interface/SimpleTransmission</type>
      <joint name="c_rod3">
          <hardwareInterface>PositionJointInterface</hardwareInterface>
      </joint>
      <actuator name="c_rod3_motor">
          <hardwareInterface>PositionJointInterface</hardwareInterface>
          <mechanicalReduction>1</mechanicalReduction>
      </actuator>
  </transmission>


  <gazebo>
    <plugin name="control" filename="libgazebo_ros_control.so"/>
  </gazebo>


  <gazebo>
    <plugin name="joint_state_publisher" filename="libgazebo_ros_joint_state_publisher.so">
      <jointName>p_motion1, p_motion2, pleatrobot_joint_1, pleatrobot_joint_2, pleatrobot_joint_3, pleatrobot_joint_4, pleatrobot_joint_5, pleatrobot_joint_6, pleatrobot_joint_7, c_rod1, p_jaw2, c_rod3</jointName>
    </plugin>
  </gazebo>

  <!-- <gazebo>
    <plugin name="joint_state_publisher" filename="libgazebo_ros_joint_state_publisher.so">
      <jointName>p_motion1, p_motion2, pleatrobot_joint_1, pleatrobot_joint_2, pleatrobot_joint_3, pleatrobot_joint_4, pleatrobot_joint_5, pleatrobot_joint_6, pleatrobot_joint_7</jointName>
    </plugin>
  </gazebo> -->

</robot>
