<?xml version="1.0" encoding="utf-8"?>
<!-- This URDF was automatically created by SolidWorks to URDF Exporter! Originally created by Stephen Brawner (brawner@gmail.com) 
     Commit Version: 1.5.1-0-g916b5db  Build Version: 1.5.7152.31018
     For more information, please see http://wiki.ros.org/sw_urdf_exporter -->
<robot
  name="gripper_description">
  <link name="base_link">
    <inertial>
      <origin
        xyz="-1.2189E-07 -1.2713 2.1759E-06"
        rpy="0 0 0" />
      <mass
        value="0.20104" />
      <inertia
        ixx="0.00012096"
        ixy="-3.4543E-10"
        ixz="7.792E-11"
        iyy="0.00021064"
        iyz="2.2037E-09"
        izz="0.00012095" />
    </inertial>
    <visual>
      <origin
        xyz="0 0 0"
        rpy="0 0 0" />
      <geometry>
        <mesh
          filename="package://gripper_description/meshes/base_link.STL" />
      </geometry>
      <material
        name="">
        <color
          rgba="0.79216 0.81961 0.93333 1" />
      </material>
    </visual>
    <collision>
      <origin
        xyz="0 0 0"
        rpy="0 0 0" />
      <geometry>
        <mesh
          filename="package://gripper_description/meshes/base_link.STL" />
      </geometry>
    </collision>
  </link>


  <link name="01_child">
    <inertial>
      <origin
        xyz="0.0094532 -1.3236 -0.0033489"
        rpy="0 0 0" />
      <mass
        value="1.3212" />
      <inertia
        ixx="0.00053176"
        ixy="3.7506E-05"
        ixz="1.1258E-09"
        iyy="0.0024257"
        iyz="4.0938E-08"
        izz="0.0021746" />
    </inertial>
    <visual>
      <origin
        xyz="0 0 0"
        rpy="0 0 0" />
      <geometry>
        <mesh
          filename="package://gripper_description/meshes/01_child.STL" />
      </geometry>
      <material
        name="">
        <color
          rgba="0.79216 0.81961 0.93333 1" />
      </material>
    </visual>
    <collision>
      <origin
        xyz="0 0 0"
        rpy="0 0 0" />
      <geometry>
        <mesh
          filename="package://gripper_description/meshes/01_child.STL" />
      </geometry>
    </collision>
  </link>


  <joint name="f_01child" type="fixed">
    <origin
      xyz="0 0 0"
      rpy="0 0 0" />
    <parent
      link="base_link" />
    <child
      link="01_child" />
    <axis
      xyz="0 0 0" />
  </joint>


  <link name="jaw1">
    <inertial>
      <origin
        xyz="-0.0085346 0.047394 0.082598"
        rpy="0 0 0" />
      <mass
        value="0.40493" />
      <inertia
        ixx="0.00035017"
        ixy="2.2144E-07"
        ixz="1.5411E-08"
        iyy="0.00038396"
        iyz="-3.3172E-05"
        izz="0.00025634" />
    </inertial>
    <visual>
      <origin
        xyz="0 0 0"
        rpy="0 0 0" />
      <geometry>
        <mesh
          filename="package://gripper_description/meshes/jaw1.STL" />
      </geometry>
      <material
        name="">
        <color
          rgba="0.82745 0.69804 0.4902 1" />
      </material>
    </visual>
    <collision>
      <origin
        xyz="0 0 0"
        rpy="0 0 0" />
      <geometry>
        <mesh
          filename="package://gripper_description/meshes/jaw1.STL" />
      </geometry>
    </collision>
  </link>
 
 
  <joint name="fixed_jaw1" type="fixed">
    <origin
      xyz="0.025 -1.503 0"
      rpy="1.5708 -1.5708 3.14159" />
    <parent
      link="01_child" />
    <child
      link="jaw1" />
    <axis
      xyz="0 0 0" />
    <limit
      lower="-0.0872665"
      upper="0.0872665"
      effort="50"
      velocity="100" />
  </joint>


  <link name="rod1">
    <inertial>
      <origin
        xyz="-0.00016212 0.079673 -0.00023128"
        rpy="0 0 0" />
      <mass
        value="0.23263" />
      <inertia
        ixx="0.00021456"
        ixy="-1.3392E-11"
        ixz="4.1162E-06"
        iyy="5.3561E-05"
        iyz="7.8804E-12"
        izz="0.00022185" />
    </inertial>
    <visual>
      <origin
        xyz="0 0 0"
        rpy="0 0 0" />
      <geometry>
        <mesh
          filename="package://gripper_description/meshes/rod1.STL" />
      </geometry>
      <material
        name="">
        <color
          rgba="0.52941 0.54902 0.54902 1" />
      </material>
    </visual>
    <collision>
      <origin
        xyz="0 0 0"
        rpy="0 0 0" />
      <geometry>
        <mesh
          filename="package://gripper_description/meshes/rod1.STL" />
      </geometry>
    </collision>
  </link>
  
  
  <joint name="c_rod1" type="continuous">
    <origin
      xyz="-0.081888 0 0"
      rpy="3.1416 0.58586 1.5708" />
    <parent
      link="jaw1" />
    <child
      link="rod1" />
    <axis
      xyz="0 1 0" />
    <limit
      effort="50"
      velocity="100" />
  </joint>
  
  
  <link name="rod2">
    <inertial>
      <origin
        xyz="-0.098 -1.328 8.1314E-17"
        rpy="0 0 0" />
      <mass
        value="0.033326" />
      <inertia
        ixx="6.3581E-07"
        ixy="3.8774E-23"
        ixz="1.6156E-23"
        iyy="6.3516E-05"
        iyz="-2.6552E-25"
        izz="6.3516E-05" />
    </inertial>
    <visual>
      <origin
        xyz="0 0 0"
        rpy="0 0 0" />
      <geometry>
        <mesh
          filename="package://gripper_description/meshes/rod2.STL" />
      </geometry>
      <material
        name="">
        <color
          rgba="0.79216 0.81961 0.93333 1" />
      </material>
    </visual>
    <collision>
      <origin
        xyz="0 0 0"
        rpy="0 0 0" />
      <geometry>
        <mesh
          filename="package://gripper_description/meshes/rod2.STL" />
      </geometry>
    </collision>
  </link>
  
  
  <joint name="f_rod2" type="fixed">
    <origin
      xyz="0 0 0"
      rpy="0 0 0" />
    <parent
      link="01_child" />
    <child
      link="rod2" />
    <axis
      xyz="0 0 0" />
  </joint>
  
  
  <link name="jaw2">
    <inertial>
      <origin
        xyz="-0.063785 -1.38 -0.002598"
        rpy="0 0 0" />
      <mass
        value="0.81068" />
      <inertia
        ixx="0.0007992"
        ixy="0.00010843"
        ixz="-1.2528E-07"
        iyy="0.00051604"
        iyz="-2.7791E-07"
        izz="0.00060318" />
    </inertial>
    <visual>
      <origin
        xyz="0 0 0"
        rpy="0 0 0" />
      <geometry>
        <mesh
          filename="package://gripper_description/meshes/jaw2.STL" />
      </geometry>
      <material
        name="">
        <color
          rgba="0.82745 0.69804 0.4902 1" />
      </material>
    </visual>
    <collision>
      <origin
        xyz="0 0 0"
        rpy="0 0 0" />
      <geometry>
        <mesh
          filename="package://gripper_description/meshes/jaw2.STL" />
      </geometry>
    </collision>
  </link>
  
  
  <joint name="p_jaw2" type="prismatic">
    <origin
      xyz="0 0 0"
      rpy="0 0 0" />
    <parent
      link="rod2" />
    <child
      link="jaw2" />
    <axis
      xyz="-1 0 0" />
    <limit
      lower="0"
      upper="0.05"
      effort="50"
      velocity="100" />
  </joint>
  
  
  <link name="rod3">
    <inertial>
      <origin
        xyz="-0.000287482481318269 0.0796731129142511 2.27008169670917E-05"
        rpy="0 0 0" />
      <mass
        value="0.232866245737791" />
      <inertia
        ixx="0.000223656460602869"
        ixy="-4.85120700596206E-13"
        ixz="7.44206671716712E-07"
        iyy="5.35773404241321E-05"
        iyz="1.44557114747249E-11"
        izz="0.000212754182688039" />
    </inertial>
    <visual>
      <origin
        xyz="0 0 0"
        rpy="0 0 0" />
      <geometry>
        <mesh
          filename="package://gripper_description/meshes/rod3.STL" />
      </geometry>
      <material
        name="">
        <color
          rgba="0.529411764705882 0.549019607843137 0.549019607843137 1" />
      </material>
    </visual>
    <collision>
      <origin
        xyz="0 0 0"
        rpy="0 0 0" />
      <geometry>
        <mesh
          filename="package://gripper_description/meshes/rod3.STL" />
      </geometry>
    </collision>
  </link>
  
  
  <joint name="c_rod3" type="continuous">
    <origin
      xyz="-0.025 -1.503 0.081888"
      rpy="-1.5708 0 -0.55284" />
    <parent
      link="jaw2" />
    <child
      link="rod3" />
    <axis
      xyz="0 1 0" />
    <limit
      effort="50"
      velocity="100" />
  </joint>

  
</robot>