<?xml version="1.0" encoding="utf-8"?>
<!-- This URDF was automatically created by SolidWorks to URDF Exporter! Originally created by Stephen Brawner (brawner@gmail.com) 
     Commit Version: 1.5.1-0-g916b5db  Build Version: 1.5.7152.31018
     For more information, please see http://wiki.ros.org/sw_urdf_exporter -->
<robot
  name="gantry_description">
  <link name="base_link">
    <inertial>
      <origin
        xyz="0 0 0.95"
        rpy="0 0 0" />
      <mass
        value="186.7" />
      <inertia
        ixx="40.848"
        ixy="-4.946E-10"
        ixz="2.0286E-18"
        iyy="45.385"
        iyz="-1.119E-15"
        izz="5.3511" />
    </inertial>
    <visual>
      <origin rpy="0 0 0" xyz="0 0 0.95"/>
      <geometry>
        <mesh filename="package://gantry_description/meshes/base_link.STL"/>
      </geometry>
      <material name="">
        <color rgba="0.89804 0.91765 0.92941 1"/>
      </material>
    </visual>
    <collision>
      <origin rpy="0 0 0" xyz="0 0 0.95"/>
      <geometry>
        <mesh filename="package://gantry_description/meshes/base_link.STL"/>
      </geometry>
    </collision>
  </link>
  <link
    name="left_bar">
    <inertial>
      <origin rpy="0 0 0" xyz="0.82653 0.0 1.85173"/>
      <mass value="24.263"/>
      <inertia ixx="6.57" iyy="0.03" izz="6.56" ixy="0" ixz="0" iyz="0" />
    </inertial>
    <visual>
      <origin rpy="0 0 0" xyz="0 0 0.95"/>
      <geometry>
        <mesh filename="package://gantry_description/meshes/left_bar.STL"/>
      </geometry>
      <material name="">
        <color rgba="0.89804 0.91765 0.92941 1"/>
      </material>
    </visual>
    <collision>
      <origin rpy="0 0 0" xyz="0 0 0.95"/>
      <geometry>
        <mesh filename="package://gantry_description/meshes/left_bar.STL"/>
      </geometry>
    </collision>
  </link>
  
  <joint name="f_left_bar" type="fixed">
    <origin rpy="0 0 0" xyz="0 0 0"/>
    <parent link="base_link"/>
    <child link="left_bar"/>
    <axis xyz="0 0 0"/>
  </joint>
  
  
  <link name="right_bar">
    <inertial>
      <origin rpy="0 0 0" xyz="-0.82689 0 1.85173"/>
      <mass value="24.263"/>
      <inertia ixx="6.57" iyy="0.03" izz="6.56" ixy="0" ixz="0" iyz="0" />
    </inertial>
    <visual>
      <origin rpy="0 0 0" xyz="0 0 0.95"/>
      <geometry>
        <mesh filename="package://gantry_description/meshes/right_bar.STL"/>
      </geometry>
      <material name="">
        <color rgba="0.89804 0.91765 0.92941 1"/>
      </material>
    </visual>
    <collision>
      <origin rpy="0 0 0" xyz="0 0 0.95"/>
      <geometry>
        <mesh filename="package://gantry_description/meshes/right_bar.STL"/>
      </geometry>
    </collision>
  </link>


  <joint name="f_right_bar" type="fixed">
    <origin rpy="0 0 0" xyz="0 0 0"/>
    <parent link="base_link"/>
    <child link="right_bar"/>
    <axis xyz="0 0 0"/>
  </joint>
  
  <link name="right_motor">
    <inertial>
      <origin
        xyz="-0.83094 -0.60801 1.93633"
        rpy="0 0 0" />
      <mass
        value="0.512" />
      <inertia
        ixx="0.00067287"
        ixy="1.9352E-20"
        ixz="-7.5893E-08"
        iyy="0.00037705"
        iyz="-9.6171E-08"
        izz="0.00067162" />
    </inertial>
    <visual>
      <origin
        xyz="0 0 0.95"
        rpy="0 0 0" />
      <geometry>
        <mesh
          filename="package://gantry_description/meshes/right_motor.STL" />
      </geometry>
      <material
        name="">
        <color
          rgba="1 1 1 1" />
      </material>
    </visual>
    <collision>
      <origin
        xyz="0 0 0.95"
        rpy="0 0 0" />
      <geometry>
        <mesh
          filename="package://gantry_description/meshes/right_motor.STL" />
      </geometry>
    </collision>
  </link>
  <joint
    name="f_right_motor"
    type="fixed">
    <origin
      xyz="0 0 0"
      rpy="0 0 0" />
    <parent
      link="right_bar" />
    <child
      link="right_motor" />
    <axis
      xyz="0 0 0" />
  </joint>
  <link
    name="right_rod">
    <inertial>
      <origin
        xyz="-0.82757 0.09458 1.93633"
        rpy="0 0 0" />
      <mass
        value="0.02709" />
      <inertia
        ixx="4.5437E-05"
        ixy="1.1108E-11"
        ixz="-9.2199E-11"
        iyy="4.0541E-06"
        iyz="-4.9349E-11"
        izz="4.5437E-05" />
    </inertial>
    <visual>
      <origin
        xyz="0 0 0.95"
        rpy="0 0 0" />
      <geometry>
        <mesh
          filename="package://gantry_description/meshes/right_rod.STL" />
      </geometry>
      <material
        name="">
        <color
          rgba="1 0 0 1" />
      </material>
    </visual>
    <collision>
      <origin
        xyz="0 0 0.95"
        rpy="0 0 0" />
      <geometry>
        <mesh
          filename="package://gantry_description/meshes/right_rod.STL" />
      </geometry>
    </collision>
  </link>
  <joint
    name="f_right_rod"
    type="fixed">
    <origin
      xyz="0 0 0"
      rpy="0 0 0" />
    <parent
      link="right_motor" />
    <child
      link="right_rod" />
    <axis
      xyz="0 0 0" />
  </joint>
  <link
    name="motion1_slider">
    <inertial>
      <origin
        xyz="-0.82949 0.07672 1.94128"
        rpy="0 0 0" />
      <mass
        value="1.8544" />
      <inertia
        ixx="0.0032532"
        ixy="2.0988E-07"
        ixz="-4.5186E-05"
        iyy="0.00081152"
        iyz="1.6779E-07"
        izz="0.003516" />
    </inertial>
    <visual>
      <origin
        xyz="0 0 0.95"
        rpy="0 0 0" />
      <geometry>
        <mesh
          filename="package://gantry_description/meshes/motion1_slider.STL" />
      </geometry>
      <material
        name="">
        <color
          rgba="0.89804 0.91765 0.92941 1" />
      </material>
    </visual>
    <collision>
      <origin
        xyz="0 0 0.95"
        rpy="0 0 0" />
      <geometry>
        <mesh
          filename="package://gantry_description/meshes/motion1_slider.STL" />
      </geometry>
    </collision>
  </link>
  <joint
    name="p_motion1"
    type="prismatic">
    <origin
      xyz="0 0 0"
      rpy="0 0 0" />
    <parent
      link="right_rod" />
    <child
      link="motion1_slider" />
    <axis
      xyz="0 1 0" />
    <limit
      lower="-0.4"
      upper="0.4"
      effort="10"
      velocity="50" />
  </joint>
  <link
    name="top_bar">
    <inertial>
      <origin
        xyz="0.00405 0.07701 2.0363"
        rpy="0 0 0" />
      <mass
        value="10.752" />
      <inertia
        ixx="0.015147"
        ixy="3.5377E-07"
        ixz="1.4909E-05"
        iyy="1.8931"
        iyz="8.3927E-06"
        izz="1.8954" />
    </inertial>
    <visual>
      <origin
        xyz="0 0 0.95"
        rpy="0 0 0" />
      <geometry>
        <mesh
          filename="package://gantry_description/meshes/top_bar.STL" />
      </geometry>
      <material
        name="">
        <color
          rgba="0.89804 0.91765 0.92941 1" />
      </material>
    </visual>
    <collision>
      <origin
        xyz="0 0 0.95"
        rpy="0 0 0" />
      <geometry>
        <mesh
          filename="package://gantry_description/meshes/top_bar.STL" />
      </geometry>
    </collision>
  </link>
  <joint
    name="f_top_bar"
    type="fixed">
    <origin
      xyz="0 0 0"
      rpy="0 0 0" />
    <parent
      link="motion1_slider" />
    <child
      link="top_bar" />
    <axis
      xyz="0 0 0" />
  </joint>
  <link
    name="top_motor">
    <inertial>
      <origin
        xyz="-0.60801 0.07702 2.1295"
        rpy="0 0 0" />
      <mass
        value="0.512" />
      <inertia
        ixx="0.00037705"
        ixy="9.6148E-08"
        ixz="-2.118E-09"
        iyy="0.00067285"
        iyz="4.946E-08"
        izz="0.00067164" />
    </inertial>
    <visual>
      <origin
        xyz="0 0 0.95"
        rpy="0 0 0" />
      <geometry>
        <mesh
          filename="package://gantry_description/meshes/top_motor.STL" />
      </geometry>
      <material
        name="">
        <color
          rgba="1 1 1 1" />
      </material>
    </visual>
    <collision>
      <origin
        xyz="0 0 0.95"
        rpy="0 0 0" />
      <geometry>
        <mesh
          filename="package://gantry_description/meshes/top_motor.STL" />
      </geometry>
    </collision>
  </link>
  <joint
    name="f_top_motor"
    type="fixed">
    <origin
      xyz="0 0 0"
      rpy="0 0 0" />
    <parent
      link="top_bar" />
    <child
      link="top_motor" />
    <axis
      xyz="0 0 0" />
  </joint>
  <link
    name="top_rod">
    <inertial>
      <origin
        xyz="0.09323 0.07783 2.1295"
        rpy="0 0 0" />
      <mass
        value="0.02709" />
      <inertia
        ixx="4.0541E-06"
        ixy="1.4106E-11"
        ixz="-4.8609E-11"
        iyy="4.5437E-05"
        iyz="-3.8569E-11"
        izz="4.5437E-05" />
    </inertial>
    <visual>
      <origin
        xyz="0 0 0.95"
        rpy="0 0 0" />
      <geometry>
        <mesh
          filename="package://gantry_description/meshes/top_rod.STL" />
      </geometry>
      <material
        name="">
        <color
          rgba="0.68627 0.68627 0.68627 1" />
      </material>
    </visual>
    <collision>
      <origin
        xyz="0 0 0.95"
        rpy="0 0 0" />
      <geometry>
        <mesh
          filename="package://gantry_description/meshes/top_rod.STL" />
      </geometry>
    </collision>
  </link>
  <joint
    name="f_top_rod"
    type="fixed">
    <origin
      xyz="0 0 0"
      rpy="0 0 0" />
    <parent
      link="top_motor" />
    <child
      link="top_rod" />
    <axis
      xyz="0 0 0" />
  </joint>
  <link
    name="motion2_slider">
    <inertial>
      <origin
        xyz="0.04102 0.07292 2.0347"
        rpy="0 0 0" />
      <mass
        value="6.9597" />
      <inertia
        ixx="0.020511"
        ixy="-2.0988E-07"
        ixz="-1.7396E-07"
        iyy="0.037035"
        iyz="-4.3519E-11"
        izz="0.054451" />
    </inertial>
    <visual>
      <origin
        xyz="0 0 0.95"
        rpy="0 0 0" />
      <geometry>
        <mesh
          filename="package://gantry_description/meshes/motion2_slider.STL" />
      </geometry>
      <material
        name="">
        <color
          rgba="0.89804 0.91765 0.92941 1" />
      </material>
    </visual>
    <collision>
      <origin
        xyz="0 0 0.95"
        rpy="0 0 0" />
      <geometry>
        <mesh
          filename="package://gantry_description/meshes/motion2_slider.STL" />
      </geometry>
    </collision>
  </link>
  <joint
    name="p_motion2"
    type="prismatic">
    <origin
      xyz="0 0 0"
      rpy="0 0 0" />
    <parent
      link="top_rod" />
    <child
      link="motion2_slider" />
    <axis
      xyz="1 0 0" />
    <limit
      lower="-0.4"
      upper="0.4"
      effort="10"
      velocity="50" />
  </joint>
</robot>